Traceback (most recent call last):
  File "/work/pde-book/.venv/lib/python3.12/site-packages/jupyter_cache/executors/utils.py", line 58, in single_nb_execution
    executenb(
  File "/usr/lib/python3.12/site-packages/nbclient/client.py", line 1314, in execute
    return NotebookClient(nb=nb, resources=resources, km=km, **kwargs).execute()
           ^^^^^^^^^^^^^^^^^^^^^^^^^^^^^^^^^^^^^^^^^^^^^^^^^^^^^^^^^^^^^^^^^^^^^
  File "/usr/lib/python3.12/site-packages/jupyter_core/utils/__init__.py", line 165, in wrapped
    return loop.run_until_complete(inner)
           ^^^^^^^^^^^^^^^^^^^^^^^^^^^^^^
  File "/usr/lib/python3.12/asyncio/base_events.py", line 687, in run_until_complete
    return future.result()
           ^^^^^^^^^^^^^^^
  File "/usr/lib/python3.12/site-packages/nbclient/client.py", line 709, in async_execute
    await self.async_execute_cell(
  File "/usr/lib/python3.12/site-packages/nbclient/client.py", line 1062, in async_execute_cell
    await self._check_raise_for_error(cell, cell_index, exec_reply)
  File "/usr/lib/python3.12/site-packages/nbclient/client.py", line 918, in _check_raise_for_error
    raise CellExecutionError.from_cell_and_msg(cell, exec_reply_content)
nbclient.exceptions.CellExecutionError: An error occurred while executing the following cell:
------------------
field.to_file("random_field.hdf")
!(ls random_field.hdf)
------------------


[0;31m---------------------------------------------------------------------------[0m
[0;31mModuleNotFoundError[0m                       Traceback (most recent call last)
Cell [0;32mIn[20], line 1[0m
[0;32m----> 1[0m [43mfield[49m[38;5;241;43m.[39;49m[43mto_file[49m[43m([49m[38;5;124;43m"[39;49m[38;5;124;43mrandom_field.hdf[39;49m[38;5;124;43m"[39;49m[43m)[49m
[1;32m      2[0m get_ipython()[38;5;241m.[39msystem([38;5;124m'[39m[38;5;124m(ls random_field.hdf)[39m[38;5;124m'[39m)

File [0;32m/usr/lib/python3.12/site-packages/pde/fields/base.py:304[0m, in [0;36mFieldBase.to_file[0;34m(self, filename, **kwargs)[0m
[1;32m    300[0m extension [38;5;241m=[39m Path(filename)[38;5;241m.[39msuffix[38;5;241m.[39mlower()
[1;32m    302[0m [38;5;28;01mif[39;00m extension [38;5;129;01min[39;00m {[38;5;124m"[39m[38;5;124m.hdf[39m[38;5;124m"[39m, [38;5;124m"[39m[38;5;124m.hdf5[39m[38;5;124m"[39m, [38;5;124m"[39m[38;5;124m.he5[39m[38;5;124m"[39m, [38;5;124m"[39m[38;5;124m.h5[39m[38;5;124m"[39m}:
[1;32m    303[0m     [38;5;66;03m# save data in hdf5 format[39;00m
[0;32m--> 304[0m     [38;5;28;01mimport[39;00m [38;5;21;01mh5py[39;00m
[1;32m    306[0m     [38;5;28;01mwith[39;00m h5py[38;5;241m.[39mFile(filename, [38;5;124m"[39m[38;5;124mw[39m[38;5;124m"[39m) [38;5;28;01mas[39;00m fp:
[1;32m    307[0m         [38;5;28mself[39m[38;5;241m.[39m_write_hdf_dataset(fp, [38;5;241m*[39m[38;5;241m*[39mkwargs)

[0;31mModuleNotFoundError[0m: No module named 'h5py'

